<?xml version="1.0" encoding="UTF-8"?>
<!-- Generated by org.testng.reporters.JUnitReportReporter -->
<testsuite hostname="VNNOT01519" failures="8" tests="14" name="com.anhtester.Bai33_ExtentReport_testcases.LoginTest" time="142.857" errors="0" timestamp="2025-06-24T16:26:40 GMT+07:00" skipped="0">
  <testcase classname="com.anhtester.Bai33_ExtentReport_testcases.LoginTest" name="loginSuccess" time="3.961">
    <failure message="FAIL Because Still in the Login page: expected [false] but found [true]" type="java.lang.AssertionError">
      <![CDATA[java.lang.AssertionError: FAIL Because Still in the Login page: expected [false] but found [true]
at org.testng.Assert.fail(Assert.java:111)
at org.testng.Assert.failNotEquals(Assert.java:1590)
at org.testng.Assert.assertFalse(Assert.java:79)
at com.anhtester.keywords.WebUI.assertNotContains(WebUI.java:447)
at com.anhtester.Bai33_ExtentReport_pages.LoginPage.verifyLoginSuccess(LoginPage.java:40)
at com.anhtester.Bai33_ExtentReport_testcases.LoginTest.loginSuccess(LoginTest.java:25)
at java.base/jdk.internal.reflect.DirectMethodHandleAccessor.invoke(DirectMethodHandleAccessor.java:103)
at java.base/java.lang.reflect.Method.invoke(Method.java:580)
at org.testng.internal.invokers.MethodInvocationHelper.invokeMethod(MethodInvocationHelper.java:141)
at org.testng.internal.invokers.TestInvoker.invokeMethod(TestInvoker.java:687)
at org.testng.internal.invokers.TestInvoker.invokeTestMethod(TestInvoker.java:230)
at org.testng.internal.invokers.TestMethodWithDataProviderMethodWorker.call(TestMethodWithDataProviderMethodWorker.java:81)
at org.testng.internal.thread.Async$AsyncTask.run(Async.java:34)
at java.base/java.util.concurrent.ThreadPoolExecutor.runWorker(ThreadPoolExecutor.java:1144)
at java.base/java.util.concurrent.ThreadPoolExecutor$Worker.run(ThreadPoolExecutor.java:642)
at java.base/java.lang.Thread.run(Thread.java:1575)
]]>
    </failure>
  </testcase> <!-- loginSuccess -->
  <testcase classname="com.anhtester.Bai33_ExtentReport_testcases.LoginTest" name="loginSuccessFromDataProvider" time="11.968">
    <failure message="FAIL Because Still in the Login page: expected [false] but found [true]" type="java.lang.AssertionError">
      <![CDATA[java.lang.AssertionError: FAIL Because Still in the Login page: expected [false] but found [true]
at org.testng.Assert.fail(Assert.java:111)
at org.testng.Assert.failNotEquals(Assert.java:1590)
at org.testng.Assert.assertFalse(Assert.java:79)
at com.anhtester.keywords.WebUI.assertNotContains(WebUI.java:447)
at com.anhtester.Bai33_ExtentReport_pages.LoginPage.verifyLoginSuccess(LoginPage.java:40)
at com.anhtester.Bai33_ExtentReport_testcases.LoginTest.loginSuccessFromDataProvider(LoginTest.java:33)
at java.base/jdk.internal.reflect.DirectMethodHandleAccessor.invoke(DirectMethodHandleAccessor.java:103)
at java.base/java.lang.reflect.Method.invoke(Method.java:580)
at org.testng.internal.invokers.MethodInvocationHelper.invokeMethod(MethodInvocationHelper.java:141)
at org.testng.internal.invokers.TestInvoker.invokeMethod(TestInvoker.java:687)
at org.testng.internal.invokers.TestInvoker.invokeTestMethod(TestInvoker.java:230)
at org.testng.internal.invokers.TestMethodWithDataProviderMethodWorker.call(TestMethodWithDataProviderMethodWorker.java:81)
at org.testng.internal.thread.Async$AsyncTask.run(Async.java:34)
at java.base/java.util.concurrent.ThreadPoolExecutor.runWorker(ThreadPoolExecutor.java:1144)
at java.base/java.util.concurrent.ThreadPoolExecutor$Worker.run(ThreadPoolExecutor.java:642)
at java.base/java.lang.Thread.run(Thread.java:1575)
]]>
    </failure>
  </testcase> <!-- loginSuccessFromDataProvider -->
  <testcase classname="com.anhtester.Bai33_ExtentReport_testcases.LoginTest" name="loginSuccessFromDataProvider" time="9.198">
    <failure message="FAIL Because Still in the Login page: expected [false] but found [true]" type="java.lang.AssertionError">
      <![CDATA[java.lang.AssertionError: FAIL Because Still in the Login page: expected [false] but found [true]
at org.testng.Assert.fail(Assert.java:111)
at org.testng.Assert.failNotEquals(Assert.java:1590)
at org.testng.Assert.assertFalse(Assert.java:79)
at com.anhtester.keywords.WebUI.assertNotContains(WebUI.java:447)
at com.anhtester.Bai33_ExtentReport_pages.LoginPage.verifyLoginSuccess(LoginPage.java:40)
at com.anhtester.Bai33_ExtentReport_testcases.LoginTest.loginSuccessFromDataProvider(LoginTest.java:33)
at java.base/jdk.internal.reflect.DirectMethodHandleAccessor.invoke(DirectMethodHandleAccessor.java:103)
at java.base/java.lang.reflect.Method.invoke(Method.java:580)
at org.testng.internal.invokers.MethodInvocationHelper.invokeMethod(MethodInvocationHelper.java:141)
at org.testng.internal.invokers.TestInvoker.invokeMethod(TestInvoker.java:687)
at org.testng.internal.invokers.TestInvoker.invokeTestMethod(TestInvoker.java:230)
at org.testng.internal.invokers.TestMethodWithDataProviderMethodWorker.call(TestMethodWithDataProviderMethodWorker.java:81)
at org.testng.internal.thread.Async$AsyncTask.run(Async.java:34)
at java.base/java.util.concurrent.ThreadPoolExecutor.runWorker(ThreadPoolExecutor.java:1144)
at java.base/java.util.concurrent.ThreadPoolExecutor$Worker.run(ThreadPoolExecutor.java:642)
at java.base/java.lang.Thread.run(Thread.java:1575)
]]>
    </failure>
  </testcase> <!-- loginSuccessFromDataProvider -->
  <testcase classname="com.anhtester.Bai33_ExtentReport_testcases.LoginTest" name="loginSuccessFromDataProvider" time="12.525"/>
  <testcase classname="com.anhtester.Bai33_ExtentReport_testcases.LoginTest" name="loginSuccessFromDataProvider" time="11.597">
    <failure message="FAIL Because Still in the Login page: expected [false] but found [true]" type="java.lang.AssertionError">
      <![CDATA[java.lang.AssertionError: FAIL Because Still in the Login page: expected [false] but found [true]
at org.testng.Assert.fail(Assert.java:111)
at org.testng.Assert.failNotEquals(Assert.java:1590)
at org.testng.Assert.assertFalse(Assert.java:79)
at com.anhtester.keywords.WebUI.assertNotContains(WebUI.java:447)
at com.anhtester.Bai33_ExtentReport_pages.LoginPage.verifyLoginSuccess(LoginPage.java:40)
at com.anhtester.Bai33_ExtentReport_testcases.LoginTest.loginSuccessFromDataProvider(LoginTest.java:33)
at java.base/jdk.internal.reflect.DirectMethodHandleAccessor.invoke(DirectMethodHandleAccessor.java:103)
at java.base/java.lang.reflect.Method.invoke(Method.java:580)
at org.testng.internal.invokers.MethodInvocationHelper.invokeMethod(MethodInvocationHelper.java:141)
at org.testng.internal.invokers.TestInvoker.invokeMethod(TestInvoker.java:687)
at org.testng.internal.invokers.TestInvoker.invokeTestMethod(TestInvoker.java:230)
at org.testng.internal.invokers.TestMethodWithDataProviderMethodWorker.call(TestMethodWithDataProviderMethodWorker.java:81)
at org.testng.internal.thread.Async$AsyncTask.run(Async.java:34)
at java.base/java.util.concurrent.ThreadPoolExecutor.runWorker(ThreadPoolExecutor.java:1144)
at java.base/java.util.concurrent.ThreadPoolExecutor$Worker.run(ThreadPoolExecutor.java:642)
at java.base/java.lang.Thread.run(Thread.java:1575)
]]>
    </failure>
  </testcase> <!-- loginSuccessFromDataProvider -->
  <testcase classname="com.anhtester.Bai33_ExtentReport_testcases.LoginTest" name="loginSuccessFromDataProvider" time="9.881">
    <failure message="FAIL Because Still in the Login page: expected [false] but found [true]" type="java.lang.AssertionError">
      <![CDATA[java.lang.AssertionError: FAIL Because Still in the Login page: expected [false] but found [true]
at org.testng.Assert.fail(Assert.java:111)
at org.testng.Assert.failNotEquals(Assert.java:1590)
at org.testng.Assert.assertFalse(Assert.java:79)
at com.anhtester.keywords.WebUI.assertNotContains(WebUI.java:447)
at com.anhtester.Bai33_ExtentReport_pages.LoginPage.verifyLoginSuccess(LoginPage.java:40)
at com.anhtester.Bai33_ExtentReport_testcases.LoginTest.loginSuccessFromDataProvider(LoginTest.java:33)
at java.base/jdk.internal.reflect.DirectMethodHandleAccessor.invoke(DirectMethodHandleAccessor.java:103)
at java.base/java.lang.reflect.Method.invoke(Method.java:580)
at org.testng.internal.invokers.MethodInvocationHelper.invokeMethod(MethodInvocationHelper.java:141)
at org.testng.internal.invokers.TestInvoker.invokeMethod(TestInvoker.java:687)
at org.testng.internal.invokers.TestInvoker.invokeTestMethod(TestInvoker.java:230)
at org.testng.internal.invokers.TestMethodWithDataProviderMethodWorker.call(TestMethodWithDataProviderMethodWorker.java:81)
at org.testng.internal.thread.Async$AsyncTask.run(Async.java:34)
at java.base/java.util.concurrent.ThreadPoolExecutor.runWorker(ThreadPoolExecutor.java:1144)
at java.base/java.util.concurrent.ThreadPoolExecutor$Worker.run(ThreadPoolExecutor.java:642)
at java.base/java.lang.Thread.run(Thread.java:1575)
]]>
    </failure>
  </testcase> <!-- loginSuccessFromDataProvider -->
  <testcase classname="com.anhtester.Bai33_ExtentReport_testcases.LoginTest" name="loginSuccessFromDataProviderHashTable" time="11.200">
    <failure message="FAIL Because Still in the Login page: expected [false] but found [true]" type="java.lang.AssertionError">
      <![CDATA[java.lang.AssertionError: FAIL Because Still in the Login page: expected [false] but found [true]
at org.testng.Assert.fail(Assert.java:111)
at org.testng.Assert.failNotEquals(Assert.java:1590)
at org.testng.Assert.assertFalse(Assert.java:79)
at com.anhtester.keywords.WebUI.assertNotContains(WebUI.java:447)
at com.anhtester.Bai33_ExtentReport_pages.LoginPage.verifyLoginSuccess(LoginPage.java:40)
at com.anhtester.Bai33_ExtentReport_testcases.LoginTest.loginSuccessFromDataProviderHashTable(LoginTest.java:41)
at java.base/jdk.internal.reflect.DirectMethodHandleAccessor.invoke(DirectMethodHandleAccessor.java:103)
at java.base/java.lang.reflect.Method.invoke(Method.java:580)
at org.testng.internal.invokers.MethodInvocationHelper.invokeMethod(MethodInvocationHelper.java:141)
at org.testng.internal.invokers.TestInvoker.invokeMethod(TestInvoker.java:687)
at org.testng.internal.invokers.TestInvoker.invokeTestMethod(TestInvoker.java:230)
at org.testng.internal.invokers.TestMethodWithDataProviderMethodWorker.call(TestMethodWithDataProviderMethodWorker.java:81)
at org.testng.internal.thread.Async$AsyncTask.run(Async.java:34)
at java.base/java.util.concurrent.ThreadPoolExecutor.runWorker(ThreadPoolExecutor.java:1144)
at java.base/java.util.concurrent.ThreadPoolExecutor$Worker.run(ThreadPoolExecutor.java:642)
at java.base/java.lang.Thread.run(Thread.java:1575)
]]>
    </failure>
  </testcase> <!-- loginSuccessFromDataProviderHashTable -->
  <testcase classname="com.anhtester.Bai33_ExtentReport_testcases.LoginTest" name="loginSuccessFromDataProviderHashTable" time="9.468">
    <failure message="FAIL Because Still in the Login page: expected [false] but found [true]" type="java.lang.AssertionError">
      <![CDATA[java.lang.AssertionError: FAIL Because Still in the Login page: expected [false] but found [true]
at org.testng.Assert.fail(Assert.java:111)
at org.testng.Assert.failNotEquals(Assert.java:1590)
at org.testng.Assert.assertFalse(Assert.java:79)
at com.anhtester.keywords.WebUI.assertNotContains(WebUI.java:447)
at com.anhtester.Bai33_ExtentReport_pages.LoginPage.verifyLoginSuccess(LoginPage.java:40)
at com.anhtester.Bai33_ExtentReport_testcases.LoginTest.loginSuccessFromDataProviderHashTable(LoginTest.java:41)
at java.base/jdk.internal.reflect.DirectMethodHandleAccessor.invoke(DirectMethodHandleAccessor.java:103)
at java.base/java.lang.reflect.Method.invoke(Method.java:580)
at org.testng.internal.invokers.MethodInvocationHelper.invokeMethod(MethodInvocationHelper.java:141)
at org.testng.internal.invokers.TestInvoker.invokeMethod(TestInvoker.java:687)
at org.testng.internal.invokers.TestInvoker.invokeTestMethod(TestInvoker.java:230)
at org.testng.internal.invokers.TestMethodWithDataProviderMethodWorker.call(TestMethodWithDataProviderMethodWorker.java:81)
at org.testng.internal.thread.Async$AsyncTask.run(Async.java:34)
at java.base/java.util.concurrent.ThreadPoolExecutor.runWorker(ThreadPoolExecutor.java:1144)
at java.base/java.util.concurrent.ThreadPoolExecutor$Worker.run(ThreadPoolExecutor.java:642)
at java.base/java.lang.Thread.run(Thread.java:1575)
]]>
    </failure>
  </testcase> <!-- loginSuccessFromDataProviderHashTable -->
  <testcase classname="com.anhtester.Bai33_ExtentReport_testcases.LoginTest" name="loginSuccessFromDataProviderHashTable" time="12.086">
    <failure message="FAIL Because Still in the Login page: expected [false] but found [true]" type="java.lang.AssertionError">
      <![CDATA[java.lang.AssertionError: FAIL Because Still in the Login page: expected [false] but found [true]
at org.testng.Assert.fail(Assert.java:111)
at org.testng.Assert.failNotEquals(Assert.java:1590)
at org.testng.Assert.assertFalse(Assert.java:79)
at com.anhtester.keywords.WebUI.assertNotContains(WebUI.java:447)
at com.anhtester.Bai33_ExtentReport_pages.LoginPage.verifyLoginSuccess(LoginPage.java:40)
at com.anhtester.Bai33_ExtentReport_testcases.LoginTest.loginSuccessFromDataProviderHashTable(LoginTest.java:41)
at java.base/jdk.internal.reflect.DirectMethodHandleAccessor.invoke(DirectMethodHandleAccessor.java:103)
at java.base/java.lang.reflect.Method.invoke(Method.java:580)
at org.testng.internal.invokers.MethodInvocationHelper.invokeMethod(MethodInvocationHelper.java:141)
at org.testng.internal.invokers.TestInvoker.invokeMethod(TestInvoker.java:687)
at org.testng.internal.invokers.TestInvoker.invokeTestMethod(TestInvoker.java:230)
at org.testng.internal.invokers.TestMethodWithDataProviderMethodWorker.call(TestMethodWithDataProviderMethodWorker.java:81)
at org.testng.internal.thread.Async$AsyncTask.run(Async.java:34)
at java.base/java.util.concurrent.ThreadPoolExecutor.runWorker(ThreadPoolExecutor.java:1144)
at java.base/java.util.concurrent.ThreadPoolExecutor$Worker.run(ThreadPoolExecutor.java:642)
at java.base/java.lang.Thread.run(Thread.java:1575)
]]>
    </failure>
  </testcase> <!-- loginSuccessFromDataProviderHashTable -->
  <testcase classname="com.anhtester.Bai33_ExtentReport_testcases.LoginTest" name="loginFailWithEmailInvalid" time="7.889"/>
  <testcase classname="com.anhtester.Bai33_ExtentReport_testcases.LoginTest" name="loginFailWithPasswordInvalid" time="10.782"/>
  <testcase classname="com.anhtester.Bai33_ExtentReport_testcases.LoginTest" name="loginFailWithEmailNull" time="11.938"/>
  <testcase classname="com.anhtester.Bai33_ExtentReport_testcases.LoginTest" name="loginFailWithPasswordNull" time="8.645"/>
  <testcase classname="com.anhtester.Bai33_ExtentReport_testcases.LoginTest" name="loginFailWithEmailNullAndPasswordNull" time="11.719"/>
</testsuite> <!-- com.anhtester.Bai33_ExtentReport_testcases.LoginTest -->
