<?xml version="1.0" encoding="UTF-8"?>
<!-- Generated by org.testng.reporters.JUnitReportReporter -->
<testsuite hostname="VNNOT01519" failures="8" tests="14" name="com.anhtester.Bai34_AllureReport_testcases.LoginTest" time="116.184" errors="0" timestamp="2025-06-26T15:45:35 GMT+07:00" skipped="0">
  <testcase classname="com.anhtester.Bai34_AllureReport_testcases.LoginTest" name="loginSuccess" time="6.915">
    <failure message="FAIL Because Still in the Login page: expected [false] but found [true]" type="java.lang.AssertionError">
      <![CDATA[java.lang.AssertionError: FAIL Because Still in the Login page: expected [false] but found [true]
at org.testng.Assert.fail(Assert.java:111)
at org.testng.Assert.failNotEquals(Assert.java:1590)
at org.testng.Assert.assertFalse(Assert.java:79)
at com.anhtester.keywords.WebUI.assertNotContains(WebUI.java:459)
at com.anhtester.Bai34_AllureReport_pages.LoginPage.verifyLoginSuccess(LoginPage.java:40)
at com.anhtester.Bai34_AllureReport_testcases.LoginTest.loginSuccess(LoginTest.java:42)
at java.base/jdk.internal.reflect.DirectMethodHandleAccessor.invoke(DirectMethodHandleAccessor.java:103)
at java.base/java.lang.reflect.Method.invoke(Method.java:580)
at org.testng.internal.invokers.MethodInvocationHelper.invokeMethod(MethodInvocationHelper.java:141)
at org.testng.internal.invokers.TestInvoker.invokeMethod(TestInvoker.java:687)
at org.testng.internal.invokers.TestInvoker.invokeTestMethod(TestInvoker.java:230)
at org.testng.internal.invokers.MethodRunner.runInSequence(MethodRunner.java:63)
at org.testng.internal.invokers.TestInvoker$MethodInvocationAgent.invoke(TestInvoker.java:995)
at org.testng.internal.invokers.TestInvoker.invokeTestMethods(TestInvoker.java:203)
at org.testng.internal.invokers.TestMethodWorker.invokeTestMethods(TestMethodWorker.java:154)
at org.testng.internal.invokers.TestMethodWorker.run(TestMethodWorker.java:134)
at java.base/java.util.concurrent.Executors$RunnableAdapter.call(Executors.java:572)
at java.base/java.util.concurrent.FutureTask.run(FutureTask.java:317)
at org.testng.internal.thread.graph.TestNGFutureTask.run(TestNGFutureTask.java:22)
at java.base/java.util.concurrent.ThreadPoolExecutor.runWorker(ThreadPoolExecutor.java:1144)
at java.base/java.util.concurrent.ThreadPoolExecutor$Worker.run(ThreadPoolExecutor.java:642)
at java.base/java.lang.Thread.run(Thread.java:1575)
]]>
    </failure>
  </testcase> <!-- loginSuccess -->
  <testcase classname="com.anhtester.Bai34_AllureReport_testcases.LoginTest" name="loginSuccessFromDataProvider" time="6.221">
    <failure message="FAIL Because Still in the Login page: expected [false] but found [true]" type="java.lang.AssertionError">
      <![CDATA[java.lang.AssertionError: FAIL Because Still in the Login page: expected [false] but found [true]
at org.testng.Assert.fail(Assert.java:111)
at org.testng.Assert.failNotEquals(Assert.java:1590)
at org.testng.Assert.assertFalse(Assert.java:79)
at com.anhtester.keywords.WebUI.assertNotContains(WebUI.java:459)
at com.anhtester.Bai34_AllureReport_pages.LoginPage.verifyLoginSuccess(LoginPage.java:40)
at com.anhtester.Bai34_AllureReport_testcases.LoginTest.loginSuccessFromDataProvider(LoginTest.java:55)
at java.base/jdk.internal.reflect.DirectMethodHandleAccessor.invoke(DirectMethodHandleAccessor.java:103)
at java.base/java.lang.reflect.Method.invoke(Method.java:580)
at org.testng.internal.invokers.MethodInvocationHelper.invokeMethod(MethodInvocationHelper.java:141)
at org.testng.internal.invokers.TestInvoker.invokeMethod(TestInvoker.java:687)
at org.testng.internal.invokers.TestInvoker.invokeTestMethod(TestInvoker.java:230)
at org.testng.internal.invokers.MethodRunner.runInSequence(MethodRunner.java:63)
at org.testng.internal.invokers.TestInvoker$MethodInvocationAgent.invoke(TestInvoker.java:995)
at org.testng.internal.invokers.TestInvoker.invokeTestMethods(TestInvoker.java:203)
at org.testng.internal.invokers.TestMethodWorker.invokeTestMethods(TestMethodWorker.java:154)
at org.testng.internal.invokers.TestMethodWorker.run(TestMethodWorker.java:134)
at java.base/java.util.concurrent.Executors$RunnableAdapter.call(Executors.java:572)
at java.base/java.util.concurrent.FutureTask.run(FutureTask.java:317)
at org.testng.internal.thread.graph.TestNGFutureTask.run(TestNGFutureTask.java:22)
at java.base/java.util.concurrent.ThreadPoolExecutor.runWorker(ThreadPoolExecutor.java:1144)
at java.base/java.util.concurrent.ThreadPoolExecutor$Worker.run(ThreadPoolExecutor.java:642)
at java.base/java.lang.Thread.run(Thread.java:1575)
]]>
    </failure>
  </testcase> <!-- loginSuccessFromDataProvider -->
  <testcase classname="com.anhtester.Bai34_AllureReport_testcases.LoginTest" name="loginSuccessFromDataProvider" time="10.342">
    <failure message="FAIL Because Still in the Login page: expected [false] but found [true]" type="java.lang.AssertionError">
      <![CDATA[java.lang.AssertionError: FAIL Because Still in the Login page: expected [false] but found [true]
at org.testng.Assert.fail(Assert.java:111)
at org.testng.Assert.failNotEquals(Assert.java:1590)
at org.testng.Assert.assertFalse(Assert.java:79)
at com.anhtester.keywords.WebUI.assertNotContains(WebUI.java:459)
at com.anhtester.Bai34_AllureReport_pages.LoginPage.verifyLoginSuccess(LoginPage.java:40)
at com.anhtester.Bai34_AllureReport_testcases.LoginTest.loginSuccessFromDataProvider(LoginTest.java:55)
at java.base/jdk.internal.reflect.DirectMethodHandleAccessor.invoke(DirectMethodHandleAccessor.java:103)
at java.base/java.lang.reflect.Method.invoke(Method.java:580)
at org.testng.internal.invokers.MethodInvocationHelper.invokeMethod(MethodInvocationHelper.java:141)
at org.testng.internal.invokers.TestInvoker.invokeMethod(TestInvoker.java:687)
at org.testng.internal.invokers.TestInvoker.invokeTestMethod(TestInvoker.java:230)
at org.testng.internal.invokers.MethodRunner.runInSequence(MethodRunner.java:63)
at org.testng.internal.invokers.TestInvoker$MethodInvocationAgent.invoke(TestInvoker.java:995)
at org.testng.internal.invokers.TestInvoker.invokeTestMethods(TestInvoker.java:203)
at org.testng.internal.invokers.TestMethodWorker.invokeTestMethods(TestMethodWorker.java:154)
at org.testng.internal.invokers.TestMethodWorker.run(TestMethodWorker.java:134)
at java.base/java.util.concurrent.Executors$RunnableAdapter.call(Executors.java:572)
at java.base/java.util.concurrent.FutureTask.run(FutureTask.java:317)
at org.testng.internal.thread.graph.TestNGFutureTask.run(TestNGFutureTask.java:22)
at java.base/java.util.concurrent.ThreadPoolExecutor.runWorker(ThreadPoolExecutor.java:1144)
at java.base/java.util.concurrent.ThreadPoolExecutor$Worker.run(ThreadPoolExecutor.java:642)
at java.base/java.lang.Thread.run(Thread.java:1575)
]]>
    </failure>
  </testcase> <!-- loginSuccessFromDataProvider -->
  <testcase classname="com.anhtester.Bai34_AllureReport_testcases.LoginTest" name="loginSuccessFromDataProvider" time="11.823"/>
  <testcase classname="com.anhtester.Bai34_AllureReport_testcases.LoginTest" name="loginSuccessFromDataProvider" time="7.912">
    <failure message="FAIL Because Still in the Login page: expected [false] but found [true]" type="java.lang.AssertionError">
      <![CDATA[java.lang.AssertionError: FAIL Because Still in the Login page: expected [false] but found [true]
at org.testng.Assert.fail(Assert.java:111)
at org.testng.Assert.failNotEquals(Assert.java:1590)
at org.testng.Assert.assertFalse(Assert.java:79)
at com.anhtester.keywords.WebUI.assertNotContains(WebUI.java:459)
at com.anhtester.Bai34_AllureReport_pages.LoginPage.verifyLoginSuccess(LoginPage.java:40)
at com.anhtester.Bai34_AllureReport_testcases.LoginTest.loginSuccessFromDataProvider(LoginTest.java:55)
at java.base/jdk.internal.reflect.DirectMethodHandleAccessor.invoke(DirectMethodHandleAccessor.java:103)
at java.base/java.lang.reflect.Method.invoke(Method.java:580)
at org.testng.internal.invokers.MethodInvocationHelper.invokeMethod(MethodInvocationHelper.java:141)
at org.testng.internal.invokers.TestInvoker.invokeMethod(TestInvoker.java:687)
at org.testng.internal.invokers.TestInvoker.invokeTestMethod(TestInvoker.java:230)
at org.testng.internal.invokers.MethodRunner.runInSequence(MethodRunner.java:63)
at org.testng.internal.invokers.TestInvoker$MethodInvocationAgent.invoke(TestInvoker.java:995)
at org.testng.internal.invokers.TestInvoker.invokeTestMethods(TestInvoker.java:203)
at org.testng.internal.invokers.TestMethodWorker.invokeTestMethods(TestMethodWorker.java:154)
at org.testng.internal.invokers.TestMethodWorker.run(TestMethodWorker.java:134)
at java.base/java.util.concurrent.Executors$RunnableAdapter.call(Executors.java:572)
at java.base/java.util.concurrent.FutureTask.run(FutureTask.java:317)
at org.testng.internal.thread.graph.TestNGFutureTask.run(TestNGFutureTask.java:22)
at java.base/java.util.concurrent.ThreadPoolExecutor.runWorker(ThreadPoolExecutor.java:1144)
at java.base/java.util.concurrent.ThreadPoolExecutor$Worker.run(ThreadPoolExecutor.java:642)
at java.base/java.lang.Thread.run(Thread.java:1575)
]]>
    </failure>
  </testcase> <!-- loginSuccessFromDataProvider -->
  <testcase classname="com.anhtester.Bai34_AllureReport_testcases.LoginTest" name="loginSuccessFromDataProvider" time="7.282">
    <failure message="FAIL Because Still in the Login page: expected [false] but found [true]" type="java.lang.AssertionError">
      <![CDATA[java.lang.AssertionError: FAIL Because Still in the Login page: expected [false] but found [true]
at org.testng.Assert.fail(Assert.java:111)
at org.testng.Assert.failNotEquals(Assert.java:1590)
at org.testng.Assert.assertFalse(Assert.java:79)
at com.anhtester.keywords.WebUI.assertNotContains(WebUI.java:459)
at com.anhtester.Bai34_AllureReport_pages.LoginPage.verifyLoginSuccess(LoginPage.java:40)
at com.anhtester.Bai34_AllureReport_testcases.LoginTest.loginSuccessFromDataProvider(LoginTest.java:55)
at java.base/jdk.internal.reflect.DirectMethodHandleAccessor.invoke(DirectMethodHandleAccessor.java:103)
at java.base/java.lang.reflect.Method.invoke(Method.java:580)
at org.testng.internal.invokers.MethodInvocationHelper.invokeMethod(MethodInvocationHelper.java:141)
at org.testng.internal.invokers.TestInvoker.invokeMethod(TestInvoker.java:687)
at org.testng.internal.invokers.TestInvoker.invokeTestMethod(TestInvoker.java:230)
at org.testng.internal.invokers.MethodRunner.runInSequence(MethodRunner.java:63)
at org.testng.internal.invokers.TestInvoker$MethodInvocationAgent.invoke(TestInvoker.java:995)
at org.testng.internal.invokers.TestInvoker.invokeTestMethods(TestInvoker.java:203)
at org.testng.internal.invokers.TestMethodWorker.invokeTestMethods(TestMethodWorker.java:154)
at org.testng.internal.invokers.TestMethodWorker.run(TestMethodWorker.java:134)
at java.base/java.util.concurrent.Executors$RunnableAdapter.call(Executors.java:572)
at java.base/java.util.concurrent.FutureTask.run(FutureTask.java:317)
at org.testng.internal.thread.graph.TestNGFutureTask.run(TestNGFutureTask.java:22)
at java.base/java.util.concurrent.ThreadPoolExecutor.runWorker(ThreadPoolExecutor.java:1144)
at java.base/java.util.concurrent.ThreadPoolExecutor$Worker.run(ThreadPoolExecutor.java:642)
at java.base/java.lang.Thread.run(Thread.java:1575)
]]>
    </failure>
  </testcase> <!-- loginSuccessFromDataProvider -->
  <testcase classname="com.anhtester.Bai34_AllureReport_testcases.LoginTest" name="loginSuccessFromDataProviderHashTable" time="7.289">
    <failure message="FAIL Because Still in the Login page: expected [false] but found [true]" type="java.lang.AssertionError">
      <![CDATA[java.lang.AssertionError: FAIL Because Still in the Login page: expected [false] but found [true]
at org.testng.Assert.fail(Assert.java:111)
at org.testng.Assert.failNotEquals(Assert.java:1590)
at org.testng.Assert.assertFalse(Assert.java:79)
at com.anhtester.keywords.WebUI.assertNotContains(WebUI.java:459)
at com.anhtester.Bai34_AllureReport_pages.LoginPage.verifyLoginSuccess(LoginPage.java:40)
at com.anhtester.Bai34_AllureReport_testcases.LoginTest.loginSuccessFromDataProviderHashTable(LoginTest.java:68)
at java.base/jdk.internal.reflect.DirectMethodHandleAccessor.invoke(DirectMethodHandleAccessor.java:103)
at java.base/java.lang.reflect.Method.invoke(Method.java:580)
at org.testng.internal.invokers.MethodInvocationHelper.invokeMethod(MethodInvocationHelper.java:141)
at org.testng.internal.invokers.TestInvoker.invokeMethod(TestInvoker.java:687)
at org.testng.internal.invokers.TestInvoker.invokeTestMethod(TestInvoker.java:230)
at org.testng.internal.invokers.MethodRunner.runInSequence(MethodRunner.java:63)
at org.testng.internal.invokers.TestInvoker$MethodInvocationAgent.invoke(TestInvoker.java:995)
at org.testng.internal.invokers.TestInvoker.invokeTestMethods(TestInvoker.java:203)
at org.testng.internal.invokers.TestMethodWorker.invokeTestMethods(TestMethodWorker.java:154)
at org.testng.internal.invokers.TestMethodWorker.run(TestMethodWorker.java:134)
at java.base/java.util.concurrent.Executors$RunnableAdapter.call(Executors.java:572)
at java.base/java.util.concurrent.FutureTask.run(FutureTask.java:317)
at org.testng.internal.thread.graph.TestNGFutureTask.run(TestNGFutureTask.java:22)
at java.base/java.util.concurrent.ThreadPoolExecutor.runWorker(ThreadPoolExecutor.java:1144)
at java.base/java.util.concurrent.ThreadPoolExecutor$Worker.run(ThreadPoolExecutor.java:642)
at java.base/java.lang.Thread.run(Thread.java:1575)
]]>
    </failure>
  </testcase> <!-- loginSuccessFromDataProviderHashTable -->
  <testcase classname="com.anhtester.Bai34_AllureReport_testcases.LoginTest" name="loginSuccessFromDataProviderHashTable" time="8.511">
    <failure message="FAIL Because Still in the Login page: expected [false] but found [true]" type="java.lang.AssertionError">
      <![CDATA[java.lang.AssertionError: FAIL Because Still in the Login page: expected [false] but found [true]
at org.testng.Assert.fail(Assert.java:111)
at org.testng.Assert.failNotEquals(Assert.java:1590)
at org.testng.Assert.assertFalse(Assert.java:79)
at com.anhtester.keywords.WebUI.assertNotContains(WebUI.java:459)
at com.anhtester.Bai34_AllureReport_pages.LoginPage.verifyLoginSuccess(LoginPage.java:40)
at com.anhtester.Bai34_AllureReport_testcases.LoginTest.loginSuccessFromDataProviderHashTable(LoginTest.java:68)
at java.base/jdk.internal.reflect.DirectMethodHandleAccessor.invoke(DirectMethodHandleAccessor.java:103)
at java.base/java.lang.reflect.Method.invoke(Method.java:580)
at org.testng.internal.invokers.MethodInvocationHelper.invokeMethod(MethodInvocationHelper.java:141)
at org.testng.internal.invokers.TestInvoker.invokeMethod(TestInvoker.java:687)
at org.testng.internal.invokers.TestInvoker.invokeTestMethod(TestInvoker.java:230)
at org.testng.internal.invokers.MethodRunner.runInSequence(MethodRunner.java:63)
at org.testng.internal.invokers.TestInvoker$MethodInvocationAgent.invoke(TestInvoker.java:995)
at org.testng.internal.invokers.TestInvoker.invokeTestMethods(TestInvoker.java:203)
at org.testng.internal.invokers.TestMethodWorker.invokeTestMethods(TestMethodWorker.java:154)
at org.testng.internal.invokers.TestMethodWorker.run(TestMethodWorker.java:134)
at java.base/java.util.concurrent.Executors$RunnableAdapter.call(Executors.java:572)
at java.base/java.util.concurrent.FutureTask.run(FutureTask.java:317)
at org.testng.internal.thread.graph.TestNGFutureTask.run(TestNGFutureTask.java:22)
at java.base/java.util.concurrent.ThreadPoolExecutor.runWorker(ThreadPoolExecutor.java:1144)
at java.base/java.util.concurrent.ThreadPoolExecutor$Worker.run(ThreadPoolExecutor.java:642)
at java.base/java.lang.Thread.run(Thread.java:1575)
]]>
    </failure>
  </testcase> <!-- loginSuccessFromDataProviderHashTable -->
  <testcase classname="com.anhtester.Bai34_AllureReport_testcases.LoginTest" name="loginSuccessFromDataProviderHashTable" time="11.129">
    <failure message="FAIL Because Still in the Login page: expected [false] but found [true]" type="java.lang.AssertionError">
      <![CDATA[java.lang.AssertionError: FAIL Because Still in the Login page: expected [false] but found [true]
at org.testng.Assert.fail(Assert.java:111)
at org.testng.Assert.failNotEquals(Assert.java:1590)
at org.testng.Assert.assertFalse(Assert.java:79)
at com.anhtester.keywords.WebUI.assertNotContains(WebUI.java:459)
at com.anhtester.Bai34_AllureReport_pages.LoginPage.verifyLoginSuccess(LoginPage.java:40)
at com.anhtester.Bai34_AllureReport_testcases.LoginTest.loginSuccessFromDataProviderHashTable(LoginTest.java:68)
at java.base/jdk.internal.reflect.DirectMethodHandleAccessor.invoke(DirectMethodHandleAccessor.java:103)
at java.base/java.lang.reflect.Method.invoke(Method.java:580)
at org.testng.internal.invokers.MethodInvocationHelper.invokeMethod(MethodInvocationHelper.java:141)
at org.testng.internal.invokers.TestInvoker.invokeMethod(TestInvoker.java:687)
at org.testng.internal.invokers.TestInvoker.invokeTestMethod(TestInvoker.java:230)
at org.testng.internal.invokers.MethodRunner.runInSequence(MethodRunner.java:63)
at org.testng.internal.invokers.TestInvoker$MethodInvocationAgent.invoke(TestInvoker.java:995)
at org.testng.internal.invokers.TestInvoker.invokeTestMethods(TestInvoker.java:203)
at org.testng.internal.invokers.TestMethodWorker.invokeTestMethods(TestMethodWorker.java:154)
at org.testng.internal.invokers.TestMethodWorker.run(TestMethodWorker.java:134)
at java.base/java.util.concurrent.Executors$RunnableAdapter.call(Executors.java:572)
at java.base/java.util.concurrent.FutureTask.run(FutureTask.java:317)
at org.testng.internal.thread.graph.TestNGFutureTask.run(TestNGFutureTask.java:22)
at java.base/java.util.concurrent.ThreadPoolExecutor.runWorker(ThreadPoolExecutor.java:1144)
at java.base/java.util.concurrent.ThreadPoolExecutor$Worker.run(ThreadPoolExecutor.java:642)
at java.base/java.lang.Thread.run(Thread.java:1575)
]]>
    </failure>
  </testcase> <!-- loginSuccessFromDataProviderHashTable -->
  <testcase classname="com.anhtester.Bai34_AllureReport_testcases.LoginTest" name="loginFailWithEmailInvalid" time="7.911"/>
  <testcase classname="com.anhtester.Bai34_AllureReport_testcases.LoginTest" name="loginFailWithPasswordInvalid" time="9.046"/>
  <testcase classname="com.anhtester.Bai34_AllureReport_testcases.LoginTest" name="loginFailWithEmailNull" time="8.483"/>
  <testcase classname="com.anhtester.Bai34_AllureReport_testcases.LoginTest" name="loginFailWithPasswordNull" time="8.538"/>
  <testcase classname="com.anhtester.Bai34_AllureReport_testcases.LoginTest" name="loginFailWithEmailNullAndPasswordNull" time="4.782"/>
</testsuite> <!-- com.anhtester.Bai34_AllureReport_testcases.LoginTest -->
