<?xml version="1.0" encoding="UTF-8"?>
<!-- Generated by org.testng.reporters.JUnitReportReporter -->
<testsuite hostname="VNNOT01519" failures="3" tests="3" name="com.anhtester.Bai29_DataProvider_testcases.LoginTest" time="21.906" errors="0" timestamp="2025-06-22T00:09:33 GMT+07:00" skipped="0">
  <testcase classname="com.anhtester.Bai29_DataProvider_testcases.LoginTest" name="loginSuccessFromDataProviderHashTable" time="7.191">
    <failure message="FAIL. Vẫn đang ở trang Login expected [false] but found [true]" type="java.lang.AssertionError">
      <![CDATA[java.lang.AssertionError: FAIL. Vẫn đang ở trang Login expected [false] but found [true]
at org.testng.Assert.fail(Assert.java:111)
at org.testng.Assert.failNotEquals(Assert.java:1590)
at org.testng.Assert.assertFalse(Assert.java:79)
at com.anhtester.keywords.WebUI.assertNotContains(WebUI.java:439)
at com.anhtester.Bai29_DataProvider_pages.LoginPage.verifyLoginSuccess(LoginPage.java:47)
at com.anhtester.Bai29_DataProvider_testcases.LoginTest.loginSuccessFromDataProviderHashTable(LoginTest.java:38)
at java.base/jdk.internal.reflect.DirectMethodHandleAccessor.invoke(DirectMethodHandleAccessor.java:103)
at java.base/java.lang.reflect.Method.invoke(Method.java:580)
at org.testng.internal.invokers.MethodInvocationHelper.invokeMethod(MethodInvocationHelper.java:141)
at org.testng.internal.invokers.TestInvoker.invokeMethod(TestInvoker.java:687)
at org.testng.internal.invokers.TestInvoker.invokeTestMethod(TestInvoker.java:230)
at org.testng.internal.invokers.TestMethodWithDataProviderMethodWorker.call(TestMethodWithDataProviderMethodWorker.java:81)
at org.testng.internal.thread.Async$AsyncTask.run(Async.java:34)
at java.base/java.util.concurrent.ThreadPoolExecutor.runWorker(ThreadPoolExecutor.java:1144)
at java.base/java.util.concurrent.ThreadPoolExecutor$Worker.run(ThreadPoolExecutor.java:642)
at java.base/java.lang.Thread.run(Thread.java:1575)
]]>
    </failure>
  </testcase> <!-- loginSuccessFromDataProviderHashTable -->
  <testcase classname="com.anhtester.Bai29_DataProvider_testcases.LoginTest" name="loginSuccessFromDataProviderHashTable" time="7.392">
    <failure message="FAIL. Vẫn đang ở trang Login expected [false] but found [true]" type="java.lang.AssertionError">
      <![CDATA[java.lang.AssertionError: FAIL. Vẫn đang ở trang Login expected [false] but found [true]
at org.testng.Assert.fail(Assert.java:111)
at org.testng.Assert.failNotEquals(Assert.java:1590)
at org.testng.Assert.assertFalse(Assert.java:79)
at com.anhtester.keywords.WebUI.assertNotContains(WebUI.java:439)
at com.anhtester.Bai29_DataProvider_pages.LoginPage.verifyLoginSuccess(LoginPage.java:47)
at com.anhtester.Bai29_DataProvider_testcases.LoginTest.loginSuccessFromDataProviderHashTable(LoginTest.java:38)
at java.base/jdk.internal.reflect.DirectMethodHandleAccessor.invoke(DirectMethodHandleAccessor.java:103)
at java.base/java.lang.reflect.Method.invoke(Method.java:580)
at org.testng.internal.invokers.MethodInvocationHelper.invokeMethod(MethodInvocationHelper.java:141)
at org.testng.internal.invokers.TestInvoker.invokeMethod(TestInvoker.java:687)
at org.testng.internal.invokers.TestInvoker.invokeTestMethod(TestInvoker.java:230)
at org.testng.internal.invokers.TestMethodWithDataProviderMethodWorker.call(TestMethodWithDataProviderMethodWorker.java:81)
at org.testng.internal.thread.Async$AsyncTask.run(Async.java:34)
at java.base/java.util.concurrent.ThreadPoolExecutor.runWorker(ThreadPoolExecutor.java:1144)
at java.base/java.util.concurrent.ThreadPoolExecutor$Worker.run(ThreadPoolExecutor.java:642)
at java.base/java.lang.Thread.run(Thread.java:1575)
]]>
    </failure>
  </testcase> <!-- loginSuccessFromDataProviderHashTable -->
  <testcase classname="com.anhtester.Bai29_DataProvider_testcases.LoginTest" name="loginSuccessFromDataProviderHashTable" time="7.323">
    <failure message="FAIL. Vẫn đang ở trang Login expected [false] but found [true]" type="java.lang.AssertionError">
      <![CDATA[java.lang.AssertionError: FAIL. Vẫn đang ở trang Login expected [false] but found [true]
at org.testng.Assert.fail(Assert.java:111)
at org.testng.Assert.failNotEquals(Assert.java:1590)
at org.testng.Assert.assertFalse(Assert.java:79)
at com.anhtester.keywords.WebUI.assertNotContains(WebUI.java:439)
at com.anhtester.Bai29_DataProvider_pages.LoginPage.verifyLoginSuccess(LoginPage.java:47)
at com.anhtester.Bai29_DataProvider_testcases.LoginTest.loginSuccessFromDataProviderHashTable(LoginTest.java:38)
at java.base/jdk.internal.reflect.DirectMethodHandleAccessor.invoke(DirectMethodHandleAccessor.java:103)
at java.base/java.lang.reflect.Method.invoke(Method.java:580)
at org.testng.internal.invokers.MethodInvocationHelper.invokeMethod(MethodInvocationHelper.java:141)
at org.testng.internal.invokers.TestInvoker.invokeMethod(TestInvoker.java:687)
at org.testng.internal.invokers.TestInvoker.invokeTestMethod(TestInvoker.java:230)
at org.testng.internal.invokers.TestMethodWithDataProviderMethodWorker.call(TestMethodWithDataProviderMethodWorker.java:81)
at org.testng.internal.thread.Async$AsyncTask.run(Async.java:34)
at java.base/java.util.concurrent.ThreadPoolExecutor.runWorker(ThreadPoolExecutor.java:1144)
at java.base/java.util.concurrent.ThreadPoolExecutor$Worker.run(ThreadPoolExecutor.java:642)
at java.base/java.lang.Thread.run(Thread.java:1575)
]]>
    </failure>
  </testcase> <!-- loginSuccessFromDataProviderHashTable -->
</testsuite> <!-- com.anhtester.Bai29_DataProvider_testcases.LoginTest -->
